Workbook
Name Slicer_Discount_Category: #N/A
Name Slicer_Price_Category: #N/A

Sheet jumia_clean_dataset
A1: Product | B1: Current_price | C1: Old_price | D1: Discount | E1: Review | F1: Rating | G1: Discount | H1: Price_Category | I1: Discount_Category | J1: Rating Category
A2: 115 Piece Set Of Multifunctional Precision Screwdrivers | B2: 950 | C2: 1525 | D2: 0.38 | E2: 2 | F2: 4.5 | G2: =C2-B2 -> 575 | H2: =IF(B2<=500, "Budget", IF(B2<=1500, "Mid-Range", "Premium")) -> Mid-Range | I2: =IF(D2<0.2, "Low ", IF(D2<=0.4, "Medium", "High")) -> Medium | J2: {=_xlfn.IFS(F2="Not Rated", "Not Rated", F2<3, "Poor", F2<=4, "Average", F2<=4.5, "Good", F2>4.5, "Excellent")} -> Good
A3: Metal Decorative Hooks Key Hangers Entryway Wall Hooks Towel Hooks - Home | B3: 527 | C3: 999 | D3: 0.47 | E3: 14 | F3: 4.1 | G3: =C3-B3 -> 472 | H3: =IF(B3<=500, "Budget", IF(B3<=1500, "Mid-Range", "Premium")) -> Mid-Range | I3: =IF(D3<0.2, "Low ", IF(D3<=0.4, "Medium", "High")) -> High | J3: {=_xlfn.IFS(F3="Not Rated", "Not Rated", F3<3, "Poor", F3<=4, "Average", F3<=4.5, "Good", F3>4.5, "Excellent")} -> Good
A4: Portable Mini Cordless Car Vacuum Cleaner - Blue | B4: 2199 | C4: 2923 | D4: 0.25 | E4: 24 | F4: 4.6 | G4: =C4-B4 -> 724 | H4: =IF(B4<=500, "Budget", IF(B4<=1500, "Mid-Range", "Premium")) -> Premium | I4: =IF(D4<0.2, "Low ", IF(D4<=0.4, "Medium", "High")) -> Medium | J4: {=_xlfn.IFS(F4="Not Rated", "Not Rated", F4<3, "Poor", F4<=4, "Average", F4<=4.5, "Good", F4>4.5, "Excellent")} -> Excellent
A5: Weighing Scale Digital Bathroom Body Fat Scale USB-Black | B5: 1580 | C5: 2499 | D5: 0.37 | E5: 7 | F5: 4.7 | G5: =C5-B5 -> 919 | H5: =IF(B5<=500, "Budget", IF(B5<=1500, "Mid-Range", "Premium")) -> Premium | I5: =IF(D5<0.2, "Low ", IF(D5<=0.4, "Medium", "High")) -> Medium | J5: {=_xlfn.IFS(F5="Not Rated", "Not Rated", F5<3, "Poor", F5<=4, "Average", F5<=4.5, "Good", F5>4.5, "Excellent")} -> Excellent
A6: Portable Home Small Air Humidifier 3-Speed Fan - Green | B6: 1740 | C6: 2356 | D6: 0.26 | E6: 5 | F6: 4.8 | G6: =C6-B6 -> 616 | H6: =IF(B6<=500, "Budget", IF(B6<=1500, "Mid-Range", "Premium")) -> Premium | I6: =IF(D6<0.2, "Low ", IF(D6<=0.4, "Medium", "High")) -> Medium | J6: {=_xlfn.IFS(F6="Not Rated", "Not Rated", F6<3, "Poor", F6<=4, "Average", F6<=4.5, "Good", F6>4.5, "Excellent")} -> Excellent
A7: 220V 60W Electric Soldering Iron Kits With Tools, Tips, And Multimeter | B7: 2999 | C7: 3290 | D7: 0.09 | E7: 15 | F7: 4 | G7: =C7-B7 -> 291 | H7: =IF(B7<=500, "Budget", IF(B7<=1500, "Mid-Range", "Premium")) -> Premium | I7: =IF(D7<0.2, "Low ", IF(D7<=0.4, "Medium", "High")) -> Low | J7: {=_xlfn.IFS(F7="Not Rated", "Not Rated", F7<3, "Poor", F7<=4, "Average", F7<=4.5, "Good", F7>4.5, "Excellent")} -> Average
A8: 137 Pieces Cake Decorating Tool Set Baking Supplies | B8: 2319 | C8: 3032 | D8: 0.24 | E8: 55 | F8: 4.6 | G8: =C8-B8 -> 713 | H8: =IF(B8<=500, "Budget", IF(B8<=1500, "Mid-Range", "Premium")) -> Premium | I8: =IF(D8<0.2, "Low ", IF(D8<=0.4, "Medium", "High")) -> Medium | J8: {=_xlfn.IFS(F8="Not Rated", "Not Rated", F8<3, "Poor", F8<=4, "Average", F8<=4.5, "Good", F8>4.5, "Excellent")} -> Excellent
A9: Desk Foldable Fan Adjustable Fan Strong Wind 3 Gear Usb | B9: 988 | C9: 1580 | D9: 0.37 | E9: 2 | F9: 4 | G9: =C9-B9 -> 592 | H9: =IF(B9<=500, "Budget", IF(B9<=1500, "Mid-Range", "Premium")) -> Mid-Range | I9: =IF(D9<0.2, "Low ", IF(D9<=0.4, "Medium", "High")) -> Medium | J9: {=_xlfn.IFS(F9="Not Rated", "Not Rated", F9<3, "Poor", F9<=4, "Average", F9<=4.5, "Good", F9>4.5, "Excellent")} -> Average
A10: LASA FOLDING TABLE SERVING STAND | B10: 1274 | C10: 2800 | D10: 0.55 | E10: 5 | F10: 4.8 | G10: =C10-B10 -> 1526 | H10: =IF(B10<=500, "Budget", IF(B10<=1500, "Mid-Range", "Premium")) -> Mid-Range | I10: =IF(D10<0.2, "Low ", IF(D10<=0.4, "Medium", "High")) -> High | J10: {=_xlfn.IFS(F10="Not Rated", "Not Rated", F10<3, "Poor", F10<=4, "Average", F10<=4.5, "Good", F10>4.5, "Excellent")} -> Excellent
A11: 13 In 1 Home Repair Tools Box Kit Set | B11: 1600 | C11: 2929 | D11: 0.45 | E11: 5 | F11: 3.8 | G11: =C11-B11 -> 1329 | H11: =IF(B11<=500, "Budget", IF(B11<=1500, "Mid-Range", "Premium")) -> Premium | I11: =IF(D11<0.2, "Low ", IF(D11<=0.4, "Medium", "High")) -> High | J11: {=_xlfn.IFS(F11="Not Rated", "Not Rated", F11<3, "Poor", F11<=4, "Average", F11<=4.5, "Good", F11>4.5, "Excellent")} -> Average
A12: Genebre 115 In 1 Screwdriver Repairing Tool Set For IPhone Cellphone Hand Tool | B12: 799 | C12: 999 | D12: 0.2 | E12: 12 | F12: 4.1 | G12: =C12-B12 -> 200 | H12: =IF(B12<=500, "Budget", IF(B12<=1500, "Mid-Range", "Premium")) -> Mid-Range | I12: =IF(D12<0.2, "Low ", IF(D12<=0.4, "Medium", "High")) -> Medium | J12: {=_xlfn.IFS(F12="Not Rated", "Not Rated", F12<3, "Poor", F12<=4, "Average", F12<=4.5, "Good", F12>4.5, "Excellent")} -> Good
A13: 100 Pcs Crochet Hook Tool Set Knitting Hook Set With Box | B13: 990 | C13: 1500 | D13: 0.34 | E13: 39 | F13: 4.7 | G13: =C13-B13 -> 510 | H13: =IF(B13<=500, "Budget", IF(B13<=1500, "Mid-Range", "Premium")) -> Mid-Range | I13: =IF(D13<0.2, "Low ", IF(D13<=0.4, "Medium", "High")) -> Medium | J13: {=_xlfn.IFS(F13="Not Rated", "Not Rated", F13<3, "Poor", F13<=4, "Average", F13<=4.5, "Good", F13>4.5, "Excellent")} -> Excellent
... A22: 3PCS Single Head Knitting Crochet Sweater Needle Set | B22: 38 | C22: 80 | D22: 0.53 | E22: 13 | F22: 3.3 | G22: =C22-B22 -> 42 | H22: =IF(B22<=500, "Budget", IF(B22<=1500, "Mid-Range", "Premium")) -> Budget | I22: =IF(D22<0.2, "Low ", IF(D22<=0.4, "Medium", "High")) -> High | J22: {=_xlfn.IFS(F22="Not Rated", "Not Rated", F22<3, "Poor", F22<=4, "Average", F22<=4.5, "Good", F22>4.5, "Excellent")} -> Average
A23: 4pcs Bathroom/Kitchen Towel Rack,Roll Paper Holder,Towel Bars,Hook | B23: 1860 | C23: 3220 | D23: 0.42 | E23: 0 | F23: Not Rated | G23: =C23-B23 -> 1360 | H23: =IF(B23<=500, "Budget", IF(B23<=1500, "Mid-Range", "Premium")) -> Premium | I23: =IF(D23<0.2, "Low ", IF(D23<=0.4, "Medium", "High")) -> High | J23: {=_xlfn.IFS(F23="Not Rated", "Not Rated", F23<3, "Poor", F23<=4, "Average", F23<=4.5, "Good", F23>4.5, "Excellent")} -> Not Rated
A24: LED Romantic Spaceship Starry Sky Projector,Children's Bedroom Night Light-Blue | B24: 880 | C24: 1350 | D24: 0.35 | E24: 6 | F24: 4 | G24: =C24-B24 -> 470 | H24: =IF(B24<=500, "Budget", IF(B24<=1500, "Mid-Range", "Premium")) -> Mid-Range | I24: =IF(D24<0.2, "Low ", IF(D24<=0.4, "Medium", "High")) -> Medium | J24: {=_xlfn.IFS(F24="Not Rated", "Not Rated", F24<3, "Poor", F24<=4, "Average", F24<=4.5, "Good", F24>4.5, "Excellent")} -> Average
A25: Foldable Overbed Table/Desk | B25: 1650 | C25: 2150 | D25: 0.23 | E25: 14 | F25: 4.4 | G25: =C25-B25 -> 500 | H25: =IF(B25<=500, "Budget", IF(B25<=1500, "Mid-Range", "Premium")) -> Premium | I25: =IF(D25<0.2, "Low ", IF(D25<=0.4, "Medium", "High")) -> Medium | J25: {=_xlfn.IFS(F25="Not Rated", "Not Rated", F25<3, "Poor", F25<=4, "Average", F25<=4.5, "Good", F25>4.5, "Excellent")} -> Good
A26: LASA 3 Tier Bamboo Shoe Bench Storage Shelf | B26: 2048 | C26: 4500 | D26: 0.54 | E26: 7 | F26: 4.3 | G26: =C26-B26 -> 2452 | H26: =IF(B26<=500, "Budget", IF(B26<=1500, "Mid-Range", "Premium")) -> Premium | I26: =IF(D26<0.2, "Low ", IF(D26<=0.4, "Medium", "High")) -> High | J26: {=_xlfn.IFS(F26="Not Rated", "Not Rated", F26<3, "Poor", F26<=4, "Average", F26<=4.5, "Good", F26>4.5, "Excellent")} -> Good
A27: Electronic Digital Display Vernier Caliper | B27: 420 | C27: 647 | D27: 0.35 | E27: 49 | F27: 4.6 | G27: =C27-B27 -> 227 | H27: =IF(B27<=500, "Budget", IF(B27<=1500, "Mid-Range", "Premium")) -> Budget | I27: =IF(D27<0.2, "Low ", IF(D27<=0.4, "Medium", "High")) -> Medium | J27: {=_xlfn.IFS(F27="Not Rated", "Not Rated", F27<3, "Poor", F27<=4, "Average", F27<=4.5, "Good", F27>4.5, "Excellent")} -> Excellent
A28: Portable Wardrobe Nonwoven With 3 Hanging Rods And 6 Storage Shelves | B28: 2880 | C28: 3520 | D28: 0.18 | E28: 12 | F28: 3.8 | G28: =C28-B28 -> 640 | H28: =IF(B28<=500, "Budget", IF(B28<=1500, "Mid-Range", "Premium")) -> Premium | I28: =IF(D28<0.2, "Low ", IF(D28<=0.4, "Medium", "High")) -> Low | J28: {=_xlfn.IFS(F28="Not Rated", "Not Rated", F28<3, "Poor", F28<=4, "Average", F28<=4.5, "Good", F28>4.5, "Excellent")} -> Average
A29: 12 Litre Black Insulated Lunch Box | B29: 1350 | C29: 1990 | D29: 0.32 | E29: 13 | F29: 3.8 | G29: =C29-B29 -> 640 | H29: =IF(B29<=500, "Budget", IF(B29<=1500, "Mid-Range", "Premium")) -> Mid-Range | I29: =IF(D29<0.2, "Low ", IF(D29<=0.4, "Medium", "High")) -> Medium | J29: {=_xlfn.IFS(F29="Not Rated", "Not Rated", F29<3, "Poor", F29<=4, "Average", F29<=4.5, "Good", F29>4.5, "Excellent")} -> Average
A30: 52 Pieces Cake Decorating Tool Set Gift Kit Baking Supplies | B30: 1758 | C30: 2499 | D30: 0.3 | E30: 20 | F30: 4.1 | G30: =C30-B30 -> 741 | H30: =IF(B30<=500, "Budget", IF(B30<=1500, "Mid-Range", "Premium")) -> Premium | I30: =IF(D30<0.2, "Low ", IF(D30<=0.4, "Medium", "High")) -> Medium | J30: {=_xlfn.IFS(F30="Not Rated", "Not Rated", F30<3, "Poor", F30<=4, "Average", F30<=4.5, "Good", F30>4.5, "Excellent")} -> Good
A31: MultiFunctional Storage Rack Multi-layer Bookshelf | B31: 2200 | C31: 4080 | D31: 0.46 | E31: 0 | F31: Not Rated | G31: =C31-B31 -> 1880 | H31: =IF(B31<=500, "Budget", IF(B31<=1500, "Mid-Range", "Premium")) -> Premium | I31: =IF(D31<0.2, "Low ", IF(D31<=0.4, "Medium", "High")) -> High | J31: {=_xlfn.IFS(F31="Not Rated", "Not Rated", F31<3, "Poor", F31<=4, "Average", F31<=4.5, "Good", F31>4.5, "Excellent")} -> Not Rated
A32: Exfoliate And Exfoliate Face Towel - Black | B32: 185 | C32: 382 | D32: 0.52 | E32: 9 | F32: 4.3 | G32: =C32-B32 -> 197 | H32: =IF(B32<=500, "Budget", IF(B32<=1500, "Mid-Range", "Premium")) -> Budget | I32: =IF(D32<0.2, "Low ", IF(D32<=0.4, "Medium", "High")) -> High | J32: {=_xlfn.IFS(F32="Not Rated", "Not Rated", F32<3, "Poor", F32<=4, "Average", F32<=4.5, "Good", F32>4.5, "Excellent")} -> Good
A33: 12 Litre Insulated Lunch Box Grey | B33: 980 | C33: 1490 | D33: 0.34 | E33: 12 | F33: 4.7 | G33: =C33-B33 -> 510 | H33: =IF(B33<=500, "Budget", IF(B33<=1500, "Mid-Range", "Premium")) -> Mid-Range | I33: =IF(D33<0.2, "Low ", IF(D33<=0.4, "Medium", "High")) -> Medium | J33: {=_xlfn.IFS(F33="Not Rated", "Not Rated", F33<3, "Poor", F33<=4, "Average", F33<=4.5, "Good", F33>4.5, "Excellent")} -> Excellent
A34: LED Eye Protection Desk Lamp , Study, Reading, USB Fan - Double Pen Holder | B34: 1820 | C34: 3490 | D34: 0.48 | E34: 9 | F34: 4.3 | G34: =C34-B34 -> 1670 | H34: =IF(B34<=500, "Budget", IF(B34<=1500, "Mid-Range", "Premium")) -> Premium | I34: =IF(D34<0.2, "Low ", IF(D34<=0.4, "Medium", "High")) -> High | J34: {=_xlfn.IFS(F34="Not Rated", "Not Rated", F34<3, "Poor", F34<=4, "Average", F34<=4.5, "Good", F34>4.5, "Excellent")} -> Good
A35: 53Pcs/Set Yarn Knitting Crochet Hooks With Bag - Fortune Cat | B35: 1940 | C35: 2650 | D35: 0.27 | E35: 20 | F35: 4.7 | G35: =C35-B35 -> 710 | H35: =IF(B35<=500, "Budget", IF(B35<=1500, "Mid-Range", "Premium")) -> Premium | I35: =IF(D35<0.2, "Low ", IF(D35<=0.4, "Medium", "High")) -> Medium | J35: {=_xlfn.IFS(F35="Not Rated", "Not Rated", F35<3, "Poor", F35<=4, "Average", F35<=4.5, "Good", F35>4.5, "Excellent")} -> Excellent
A36: 53 Pieces/Set Yarn Knitting Crochet Hooks With Bag - Pansies | B36: 1980 | C36: 2699 | D36: 0.27 | E36: 32 | F36: 4.5 | G36: =C36-B36 -> 719 | H36: =IF(B36<=500, "Budget", IF(B36<=1500, "Mid-Range", "Premium")) -> Premium | I36: =IF(D36<0.2, "Low ", IF(D36<=0.4, "Medium", "High")) -> Medium | J36: {=_xlfn.IFS(F36="Not Rated", "Not Rated", F36<3, "Poor", F36<=4, "Average", F36<=4.5, "Good", F36>4.5, "Excellent")} -> Good
A37: DIY File Folder, Office Drawer File Holder, Pen Holder, Desktop Storage Rack | B37: 1620 | C37: 2690 | D37: 0.4 | E37: 1 | F37: 5 | G37: =C37-B37 -> 1070 | H37: =IF(B37<=500, "Budget", IF(B37<=1500, "Mid-Range", "Premium")) -> Premium | I37: =IF(D37<0.2, "Low ", IF(D37<=0.4, "Medium", "High")) -> Medium | J37: {=_xlfn.IFS(F37="Not Rated", "Not Rated", F37<3, "Poor", F37<=4, "Average", F37<=4.5, "Good", F37>4.5, "Excellent")} -> Excellent
A38: Classic Black Cat Cotton Hemp Pillow Case For Home Car | B38: 171 | C38: 360 | D38: 0.53 | E38: 2 | F38: 5 | G38: =C38-B38 -> 189 | H38: =IF(B38<=500, "Budget", IF(B38<=1500, "Mid-Range", "Premium")) -> Budget | I38: =IF(D38<0.2, "Low ", IF(D38<=0.4, "Medium", "High")) -> High | J38: {=_xlfn.IFS(F38="Not Rated", "Not Rated", F38<3, "Poor", F38<=4, "Average", F38<=4.5, "Good", F38>4.5, "Excellent")} -> Excellent
A39: Punch-free Great Load Bearing Bathroom Storage Rack Wall Shelf-White | B39: 389 | C39: 656 | D39: 0.41 | E39: 36 | F39: 4.3 | G39: =C39-B39 -> 267 | H39: =IF(B39<=500, "Budget", IF(B39<=1500, "Mid-Range", "Premium")) -> Budget | I39: =IF(D39<0.2, "Low ", IF(D39<=0.4, "Medium", "High")) -> High | J39: {=_xlfn.IFS(F39="Not Rated", "Not Rated", F39<3, "Poor", F39<=4, "Average", F39<=4.5, "Good", F39>4.5, "Excellent")} -> Good
A40: 1/2/3 Seater Elastic Sofa Cover,Living Room/Home Decor Chair Cover-Grey | B40: 1800 | C40: 2700 | D40: 0.38 | E40: 2 | F40: 4.5 | G40: =C40-B40 -> 900 | H40: =IF(B40<=500, "Budget", IF(B40<=1500, "Mid-Range", "Premium")) -> Premium | I40: =IF(D40<0.2, "Low ", IF(D40<=0.4, "Medium", "High")) -> Medium | J40: {=_xlfn.IFS(F40="Not Rated", "Not Rated", F40<3, "Poor", F40<=4, "Average", F40<=4.5, "Good", F40>4.5, "Excellent")} -> Good
A41: LASA Stainless Steel Double Wall Mount Soap Dispenser - 500ml | B41: 2750 | C41: 4471 | D41: 0.38 | E41: 0 | F41: Not Rated | G41: =C41-B41 -> 1721 | H41: =IF(B41<=500, "Budget", IF(B41<=1500, "Mid-Range", "Premium")) -> Premium | I41: =IF(D41<0.2, "Low ", IF(D41<=0.4, "Medium", "High")) -> Medium | J41: {=_xlfn.IFS(F41="Not Rated", "Not Rated", F41<3, "Poor", F41<=4, "Average", F41<=4.5, "Good", F41>4.5, "Excellent")} -> Not Rated
A42: 4M Float Switch Water Level Controller -Water Tank | B42: 475 | C42: 931 | D42: 0.49 | E42: 0 | F42: Not Rated | G42: =C42-B42 -> 456 | H42: =IF(B42<=500, "Budget", IF(B42<=1500, "Mid-Range", "Premium")) -> Budget | I42: =IF(D42<0.2, "Low ", IF(D42<=0.4, "Medium", "High")) -> High | J42: {=_xlfn.IFS(F42="Not Rated", "Not Rated", F42<3, "Poor", F42<=4, "Average", F42<=4.5, "Good", F42>4.5, "Excellent")} -> Not Rated
A43: Modern Sofa Throw Pillow Cover-45x45cm-Blue&Red | B43: 238 | C43: 476 | D43: 0.5 | E43: 0 | F43: Not Rated | G43: =C43-B43 -> 238 | H43: =IF(B43<=500, "Budget", IF(B43<=1500, "Mid-Range", "Premium")) -> Budget | I43: =IF(D43<0.2, "Low ", IF(D43<=0.4, "Medium", "High")) -> High | J43: {=_xlfn.IFS(F43="Not Rated", "Not Rated", F43<3, "Poor", F43<=4, "Average", F43<=4.5, "Good", F43>4.5, "Excellent")} -> Not Rated
A44: Balloon Insert, Birthday Party Balloon Set, PU Leather | B44: 610 | C44: 1060 | D44: 0.42 | E44: 0 | F44: Not Rated | G44: =C44-B44 -> 450 | H44: =IF(B44<=500, "Budget", IF(B44<=1500, "Mid-Range", "Premium")) -> Mid-Range | I44: =IF(D44<0.2, "Low ", IF(D44<=0.4, "Medium", "High")) -> High | J44: {=_xlfn.IFS(F44="Not Rated", "Not Rated", F44<3, "Poor", F44<=4, "Average", F44<=4.5, "Good", F44>4.5, "Excellent")} -> Not Rated
A45: Shower Cap Wide Elastic Band Cover Reusable Bashroom Cap | B45: 2132 | C45: 2169 | D45: 0.02 | E45: 0 | F45: Not Rated | G45: =C45-B45 -> 37 | H45: =IF(B45<=500, "Budget", IF(B45<=1500, "Mid-Range", "Premium")) -> Premium | I45: =IF(D45<0.2, "Low ", IF(D45<=0.4, "Medium", "High")) -> Low | J45: {=_xlfn.IFS(F45="Not Rated", "Not Rated", F45<3, "Poor", F45<=4, "Average", F45<=4.5, "Good", F45>4.5, "Excellent")} -> Not Rated
A46: Christmas Elk Fence Yard Lawn Decorations Cute For Holidays | B46: 999 | C46: 2000 | D46: 0.5 | E46: 0 | F46: Not Rated | G46: =C46-B46 -> 1001 | H46: =IF(B46<=500, "Budget", IF(B46<=1500, "Mid-Range", "Premium")) -> Mid-Range | I46: =IF(D46<0.2, "Low ", IF(D46<=0.4, "Medium", "High")) -> High | J46: {=_xlfn.IFS(F46="Not Rated", "Not Rated", F46<3, "Poor", F46<=4, "Average", F46<=4.5, "Good", F46>4.5, "Excellent")} -> Not Rated
A47: 60W Hot Melt Glue Sprayer - Efficient And Stable Glue Dispensing | B47: 1190 | C47: 1785 | D47: 0.33 | E47: 0 | F47: Not Rated | G47: =C47-B47 -> 595 | H47: =IF(B47<=500, "Budget", IF(B47<=1500, "Mid-Range", "Premium")) -> Mid-Range | I47: =IF(D47<0.2, "Low ", IF(D47<=0.4, "Medium", "High")) -> Medium | J47: {=_xlfn.IFS(F47="Not Rated", "Not Rated", F47<3, "Poor", F47<=4, "Average", F47<=4.5, "Good", F47>4.5, "Excellent")} -> Not Rated
A48: Car Phone Charging Stand | B48: 671 | C48: 1316 | D48: 0.49 | E48: 0 | F48: Not Rated | G48: =C48-B48 -> 645 | H48: =IF(B48<=500, "Budget", IF(B48<=1500, "Mid-Range", "Premium")) -> Mid-Range | I48: =IF(D48<0.2, "Low ", IF(D48<=0.4, "Medium", "High")) -> High | J48: {=_xlfn.IFS(F48="Not Rated", "Not Rated", F48<3, "Poor", F48<=4, "Average", F48<=4.5, "Good", F48>4.5, "Excellent")} -> Not Rated
...

Sheet Dashboard analysis
H2: Discount Category
A3: Total Products | B3: =COUNTA('[1]Cleaned Data'!A2:A113) -> 112 | H3: Row Labels | I3: Sum of Review | J3: Count of Product
A4: Total Reviews | B4: =SUM(jumia_clean_dataset!E2:E113) -> 723 | H4: High | I4: 334 | J4: 62
A5: Avg Current Price | B5: =AVERAGE(jumia_clean_dataset!B2:B113) -> 1186.8929 | H5: Low | I5: 38 | J5: 18
A6: Avg Old Price | B6: =AVERAGE(jumia_clean_dataset!C2:C113) -> 1811.1071 | H6: Medium | I6: 351 | J6: 32
A7: Avg Discount % | B7: =AVERAGE(jumia_clean_dataset!D2:D113) -> 0.36776786 | H7: Grand Total | I7: 723 | J7: 112
A8: Avg Product Rating | B8: =AVERAGEIF(jumia_clean_dataset!F2:F113, "<>Not Rated") -> 3.8894737
A10: Price Category | H10: Rating Category
A11: Row Labels | B11: Sum of Review | C11: Count of Product | H11: Row Labels | I11: Sum of Review | J11: Count of Product
A12: Budget | B12: 232 | C12: 29 | H12: Average | I12: 93 | J12: 13
A13: Mid-Range | B13: 209 | C13: 46 | H13: Excellent | I13: 289 | J13: 19
A14: Premium | B14: 282 | C14: 37 | H14: Good | I14: 172 | J14: 13
A15: Grand Total | B15: 723 | C15: 112 | H15: Not Rated | I15: 0 | J15: 55
H16: Poor | I16: 169 | J16: 12
H17: Grand Total | I17: 723 | J17: 112
A19: Extreme Category | B19: Product Name | C19: Price(Ksh)
A20: Most Expensive Product | B20: =INDEX(jumia_clean_dataset!$A$2:$A$113, MATCH(C20, jumia_clean_dataset!$B$2:$B$113, 0)) -> 32PCS Portable Cordless Drill Set With Cyclic Battery Drive -26 Variable Speed | C20: =MAX(jumia_clean_dataset!B2:B113) -> 3750
A21: Least Expensice Product | B21: =INDEX(jumia_clean_dataset!$A$2:$A$113, MATCH(C21, jumia_clean_dataset!$B$2:$B$113, 0)) -> 3PCS Single Head Knitting Crochet Sweater Needle Set | C21: =MIN(jumia_clean_dataset!B2:B113) -> 38

Sheet Dashboard
